<mujoco model="yuelu">
  <compiler angle="radian" meshdir="../meshes/"/>

  <asset>
    <mesh name="base_link" file="base_link.STL"/>
    <mesh name="lf0_Link" file="lf0_Link.STL"/>
    <mesh name="lf1_Link" file="lf1_Link.STL"/>
    <mesh name="l_wheel_Link" file="l_wheel_Link.STL"/>
    <mesh name="rf0_Link" file="rf0_Link.STL"/>
    <mesh name="rf1_Link" file="rf1_Link.STL"/>
    <mesh name="r_wheel_Link" file="r_wheel_Link.STL"/>
  </asset>

  <worldbody>
    <body name="base_link" pos="0 0 0.3" euler="0 0 0">
      <freejoint name="float_base" />
      <inertial  pos="-0.0061715 -3.7466E-05 -0.0029774" mass="10.11422856" fullinertia="0.17836415 0.13855256 0.23286100 0.00003085 0.00181870 0.00001796" />
      <geom type="mesh" contype="0" conaffinity="0" group="1" density="0" rgba="0.89804 0.91765 0.92941 1" mesh="base_link"/>
      <geom type="mesh" rgba="0.89804 0.91765 0.92941 1" mesh="base_link"/>
      <body name="lf0_Link" pos="-0.08749 0.15432 -0.0073" quat="-2.59734e-06 -2.59735e-06 -0.707108 -0.707105">
        <inertial pos="0.092242 -0.0019099 0.0073489" quat="0.00992932 0.733751 0.0113957 0.679251" mass="0.199365" diaginertia="0.00260431 0.00257696 5.93233e-05"/>
        <joint name="lf0_Joint" pos="0 0 0" axis="0 0 1" range="-1.31 0.58" actuatorfrcrange="-50 50"/>
        <geom type="mesh" contype="0" conaffinity="0" group="1" density="0" rgba="0.92941 0.92941 0.92941 1" mesh="lf0_Link"/>
        <geom type="mesh" rgba="0.92941 0.92941 0.92941 1" mesh="lf0_Link"/>
        <body name="lf1_Link" pos="0.15 0 0.012" quat="0.707105 0 0 -0.707108">
          <inertial pos="0.12277 0.0022818 0.013173" quat="0.0833826 0.723067 0.0796511 0.681086" mass="0.224049" diaginertia="0.00576178 0.00571632 9.38716e-05"/>
          <joint name="lf1_Joint" pos="0 0 0" axis="0 0 1" range="-1.4 0.8" actuatorfrcrange="-50 50"/>
          <geom type="mesh" contype="0" conaffinity="0" group="1" density="0" rgba="0.92941 0.92941 0.92941 1" mesh="lf1_Link"/>
          <geom type="mesh" rgba="0.92941 0.92941 0.92941 1" mesh="lf1_Link"/>
          <body name="l_wheel_Link" pos="0.27 0 0.018">
            <inertial pos="0.00010163 1.3317e-05 0.014296" quat="0.608014 0.361185 -0.60783 0.36112" mass="0.315382" diaginertia="0.00092103 0.000553091 0.000551949"/>
            <joint name="l_wheel_Joint" pos="0 0 0" axis="0 0 1" actuatorfrcrange="-5 5"/>
            <geom type="mesh" contype="0" conaffinity="0" group="1" density="0" rgba="1 1 1 1" mesh="l_wheel_Link"/>
            <geom size="0.078 0.011" pos="0 0 0.016" type="cylinder" rgba="1 1 1 1"/>
          </body>
        </body>
      </body>
      <body name="rf0_Link" pos="-0.08749 -0.15508 -0.0073" quat="-2.59734e-06 2.59735e-06 0.707108 -0.707105">
        <inertial pos="0.092242 0.0017673 0.0073431" quat="-0.010942 0.733723 -0.0128816 0.679238" mass="0.199365" diaginertia="0.00260431 0.00257696 5.93332e-05"/>
        <joint name="rf0_Joint" pos="0 0 0" axis="0 0 1" range="-0.58 1.31" actuatorfrcrange="-50 50"/>
        <geom type="mesh" contype="0" conaffinity="0" group="1" density="0" rgba="0.92941 0.92941 0.92941 1" mesh="rf0_Link"/>
        <geom type="mesh" rgba="0.92941 0.92941 0.92941 1" mesh="rf0_Link"/>
        <body name="rf1_Link" pos="0.15 0 0.012" quat="0.707105 0 0 0.707108">
          <inertial pos="0.12277 -0.0022788 0.013173" quat="-0.0832463 0.723084 -0.0795066 0.681101" mass="0.224049" diaginertia="0.00576177 0.00571633 9.38693e-05"/>
          <joint name="rf1_Joint" pos="0 0 0" axis="0 0 1" range="-0.8 1.4" actuatorfrcrange="-50 50"/>
          <geom type="mesh" contype="0" conaffinity="0" group="1" density="0" rgba="0.92941 0.92941 0.92941 1" mesh="rf1_Link"/>
          <geom type="mesh" rgba="0.92941 0.92941 0.92941 1" mesh="rf1_Link"/>
          <body name="r_wheel_Link" pos="0.27 0 0.018">
            <inertial pos="-6.2448e-05 -8.1281e-05 0.014296" quat="0.462645 0.534675 -0.462837 0.534662" mass="0.315382" diaginertia="0.00092103 0.000552656 0.000552374"/>
            <joint name="r_wheel_Joint" pos="0 0 0" axis="0 0 1" actuatorfrcrange="-5 5"/>
            <geom type="mesh" contype="0" conaffinity="0" group="1" density="0" rgba="1 1 1 1" mesh="r_wheel_Link"/>
            <geom size="0.078 0.011" pos="0 0 0.016" type="cylinder" rgba="1 1 1 1"/>
          </body>
        </body>
      </body>
    </body>
  </worldbody>
</mujoco>
